Workbook

Sheet 2022-2026 IRS Updates
A1: 2022-2026 IRS Tax Code Updates
A2: Prepared: April 2026 | Sources: IRS Rev. Procs. 2021-45, 2022-38, 2023-34, 2024-40, 2025-32; SSA OASDI & Medicare; One Big Beautiful Bill Act (July 2025)
A3: Legend: | B3: Blue text = hardcoded inputs from official sources | E3: Yellow = unconfirmed - needs review
A5: Social Security Taxable Wages & Medicare Rates
A6: Tax Year | B6: SS Tax Rate | C6: Max Wage Base ($) | D6: Medicare Tax Rate | E6: Addl Medicare (>$200K)
A7: 2022 | B7: 0.062 | C7: 147000 | D7: 0.0145 | E7: 0.009
A8: 2023 | B8: 0.062 | C8: 160200 | D8: 0.0145 | E8: 0.009
A9: 2024 | B9: 0.062 | C9: 168600 | D9: 0.0145 | E9: 0.009
A10: 2025 | B10: 0.062 | C10: 176100 | D10: 0.0145 | E10: 0.009
A11: 2026 | B11: 0.062 | C11: 184500 | D11: 0.0145 | E11: 0.009
A13: Source: SSA Fact Sheet on 2022-2026 Social Security Changes; ssa.gov/OACT/COLA/cbb.html
A15: Standard Deduction by Filing Status
A16: Tax Year | B16: MFJ / QSS ($) | C16: Single ($) | D16: HoH ($) | E16: MFS ($)
A17: 2022 | B17: 25900 | C17: 12950 | D17: 19400 | E17: 12950
A18: 2023 | B18: 27700 | C18: 13850 | D18: 20800 | E18: 13850
A19: 2024 | B19: 29200 | C19: 14600 | D19: 21900 | E19: 14600
A20: 2025 | B20: 31500 | C20: 15750 | D20: 23625 | E20: 15750
A21: 2026 | B21: 32200 | C21: 16100 | D21: 24150 | E21: 16100
A23: Source: IRS Rev. Proc. 2021-45, 2022-38, 2023-34, 2024-40, 2025-32
A25: Alternative Minimum Tax (AMT)
A26: AMT Exemption
A27: Tax Year | B27: MFJ ($) | C27: Single / HoH ($) | D27: MFS ($)
A28: 2022 | B28: 118100 | C28: 75900 | D28: 59050
A29: 2023 | B29: 126500 | C29: 81300 | D29: 63250
A30: 2024 | B30: 133300 | C30: 85700 | D30: 66650
A31: 2025 | B31: 137000 | C31: 88100 | D31: 68500
A32: 2026 | B32: 140200 | C32: 90100 | D32: 70100
A34: AMT 26%/28% Breakpoint
A35: Tax Year | B35: MFJ / Single / HoH ($) | C35: MFS ($)
A36: 2022 | B36: 206100 | C36: 103050
A37: 2023 | B37: 220700 | C37: 110350
A38: 2024 | B38: 232600 | C38: 116300
A39: 2025 | B39: 239100 | C39: 119550
A40: 2026 | B40: 244500 | C40: 122250
A42: AMT Exemption Phase-out Threshold Start
A43: Tax Year | B43: MFJ ($) | C43: Single / HoH ($) | D43: MFS ($)
A44: 2022 | B44: 1079800 | C44: 539900 | D44: 539900
A45: 2023 | B45: 1156300 | C45: 578150 | D45: 578150
A46: 2024 | B46: 1218700 | C46: 609350 | D46: 609350
A47: 2025 | B47: 1252700 | C47: 626350 | D47: 626350
...

Sheet General
A1: Revision History
A3: 44119 | B3: V2021.0 | C3: New version for the 2021 tax year.
A6: IRC 7520 Rate
A7: Historic IRC 7520 Rates | B7: Dec | C7: Nov | D7: Oct | E7: Sep | F7: Aug | G7: Jul | H7: Jun | I7: May | J7: Apr | K7: Mar | L7: Feb | M7: Jan
A8: For 2020 | B8: 0.006 | C8: 0.004 | D8: 0.004 | E8: 0.004 | F8: 0.004 | G8: 0.006 | H8: 0.006 | I8: 0.008 | J8: 0.012 | K8: 0.018 | L8: 0.022 | M8: 0.02
A9: For 2019 | B9: 0.02 | C9: 0.02 | D9: 0.018 | E9: 0.022 | F9: 0.022 | G9: 0.026 | H9: 0.028 | I9: 0.028 | J9: 0.03 | K9: 0.032 | L9: 0.032 | M9: 0.034
A10: For 2018 | B10: 0.036 | C10: 0.036 | D10: 0.034 | E10: 0.034 | F10: 0.034 | G10: 0.034 | H10: 0.034 | I10: 0.032 | J10: 0.032 | K10: 0.03 | L10: 0.028 | M10: 0.026
A11: For 2017 | B11: 0.026 | C11: 0.024 | D11: 0.022 | E11: 0.024 | F11: 0.024 | G11: 0.022 | H11: 0.024 | I11: 0.024 | J11: 0.026 | K11: 0.024 | L11: 0.026 | M11: 0.024
A12: For 2016 | B12: 0.018 | C12: 0.016 | D12: 0.016 | E12: 0.014 | F12: 0.014 | G12: 0.018 | H12: 0.018 | I12: 0.018 | J12: 0.018 | K12: 0.018 | L12: 0.022 | M12: 0.022
A13: For 2015 | B13: 0.02 | C13: 0.02 | D13: 0.02 | E13: 0.022 | F13: 0.022 | G13: 0.022 | H13: 0.02 | I13: 0.018 | J13: 0.02 | K13: 0.018 | L13: 0.02 | M13: 0.022
A14: For 2014 | B14: 0.02 | C14: 0.022 | D14: 0.0222 | E14: 0.022 | F14: 0.022 | G14: 0.022 | H14: 0.022 | I14: 0.024 | J14: 0.022 | K14: 0.022 | L14: 0.022 | M14: 0.022
A15: For 2013 | B15: 0.02 | C15: 0.02 | D15: 0.024 | E15: 0.02 | F15: 0.02 | G15: 0.014 | H15: 0.012 | I15: 0.012 | J15: 0.014 | K15: 0.014 | L15: 0.012 | M15: 0.01
A16: For 2012 | B16: 0.012 | C16: 0.01 | D16: 0.012 | E16: 0.01 | F16: 0.01 | G16: 0.012 | H16: 0.012 | I16: 0.016 | J16: 0.014 | K16: 0.014 | L16: 0.014 | M16: 0.014
A17: For 2011 | B17: 0.016 | C17: 0.014 | D17: 0.014 | E17: 0.02 | F17: 0.022 | G17: 0.024 | H17: 0.028 | I17: 0.03 | J17: 0.03 | K17: 0.03 | L17: 0.028 | M17: 0.024
A18: For 2010 | B18: 0.018 | C18: 0.02 | D18: 0.02 | E18: 0.024 | F18: 0.026 | G18: 0.028 | H18: 0.032 | I18: 0.034 | J18: 0.032 | K18: 0.032 | L18: 0.034 | M18: 0.03
A19: For 2009 | B19: 0.032 | C19: 0.032 | D19: 0.032 | E19: 0.034 | F19: 0.034 | G19: 0.034 | H19: 0.028 | I19: 0.024 | J19: 0.026 | K19: 0.024 | L19: 0.02 | M19: 0.024
... A24: For 2004 | B24: 0.042 | C24: 0.042 | D24: 0.044 | E24: 0.048 | F24: 0.046 | G24: 0.05 | H24: 0.046 | I24: 0.038 | J24: 0.038 | K24: 0.04 | L24: 0.042 | M24: 0.042

Sheet Tax Values
A1: Income Tax Rates / Values
A2: NOTE: All values based upon "taxable year".
A3: These are IRS published values. The raw values that we use are under the tabs showing tax law extension.
A4: *** See "2022-2026 IRS Updates" sheet for complete updated 2022-2026 values from IRS Rev. Procs. 2021-45 through 2025-32 and OBBBA 2025 ***
A5: Social Security Taxable Wages
A6: Tax Year | B6: Soc Sec Tax Rate | C6: Max Wages | D6: Medicare Tax Rate
A7: =A8+1 -> 2022 | B7: 0.062 | C7: 147000 | D7: 0.0145
A8: =A9+1 -> 2021 | B8: 0.062 | C8: 142800 | D8: 0.0145
A9: =A10+1 -> 2020 | B9: 0.062 | C9: 137700 | D9: 0.0145
A10: =A11+1 -> 2019 | B10: 0.062 | C10: 132900 | D10: 0.0145
A11: =A12+1 -> 2018 | B11: 0.062 | C11: 130500 | D11: 0.0145
A12: =A13+1 -> 2017 | B12: 0.062 | C12: 127200 | D12: 0.0145
A13: =A14+1 -> 2016 | B13: 0.062 | C13: 118500 | D13: 0.0145 | E13: * no change from 2015
A14: =A15+1 -> 2015 | B14: 0.062 | C14: 118500 | D14: 0.0145
A15: =A16+1 -> 2014 | B15: 0.062 | C15: 117000 | D15: 0.0145
A16: =A17+1 -> 2013 | B16: 0.062 | C16: 113700 | D16: 0.0145 | E16: * returned to 6.2% per American Taxpayer Relief Act of 2012
A17: =A18+1 -> 2012 | B17: 0.042 | C17: 110100 | D17: 0.0145 | E17: * one year reduction only by Congress Dec '11
A18: =A19+1 -> 2011 | B18: 0.042 | C18: 106800 | D18: 0.0145 | E18: * one year reduction only by Congress Dec '10
A19: =A20+1 -> 2010 | B19: 0.062 | C19: 106800 | D19: 0.0145
A20: =A21+1 -> 2009 | B20: 0.062 | C20: 106800 | D20: 0.0145
A21: =A22+1 -> 2008 | B21: 0.062 | C21: 102000 | D21: 0.0145
A22: =A23+1 -> 2007 | B22: 0.062 | C22: 97500 | D22: 0.0145
A23: =A24+1 -> 2006 | B23: 0.062 | C23: 94200 | D23: 0.0145
A24: =A25+1 -> 2005 | B24: 0.062 | C24: 90000 | D24: 0.0145
A25: =A26+1 -> 2004 | B25: 0.062 | C25: 87900 | D25: 0.0145
A26: =A27+1 -> 2003 | B26: 0.062 | C26: 87000 | D26: 0.0145
A27: =A28+1 -> 2002 | B27: 0.062 | C27: 84900 | D27: 0.0145
A28: =A29+1 -> 2001 | B28: 0.062 | C28: 80400 | D28: 0.0145
A29: 2000 | B29: 0.062 | C29: 76200 | D29: 0.0145
A32: Standard Deduction | H32: Standard Deduction (for 2026 Sunset)
A33: Tax Year | B33: Joint * | C33: Single | D33: Joint vs. Single Ratio | E33: Head of Household | F33: Separate | H33: Tax Year | I33: Joint * | J33: Single | K33: Joint vs. Single Ratio | L33: Head of Household | M33: Separate
A34: =A35+1 -> 2022 | B34: ='Tax Value Calcs'!D21 -> 25800 | C34: ='Tax Value Calcs'!F21 -> 12900 | D34: =B34/C34 -> 2 | E34: ='Tax Value Calcs'!H21 -> 19400 | F34: ='Tax Value Calcs'!J21 -> 12900 | H34: =H35+1 -> 2022 | I34: ='Tax Value Calcs'!I33 -> 14000 | J34: ='Tax Value Calcs'!K33 -> 7000 | K34: =I34/J34 -> 2 | L34: ='Tax Value Calcs'!M33 -> 10250 | M34: ='Tax Value Calcs'!O33 -> 7000
A35: =A36+1 -> 2021 | B35: ='Tax Value Calcs'!D22 -> 25100 | C35: ='Tax Value Calcs'!F22 -> 12550 | D35: =B35/C35 -> 2 | E35: ='Tax Value Calcs'!H22 -> 18800 | F35: ='Tax Value Calcs'!J22 -> 12550 | H35: =H36+1 -> 2021 | I35: ='Tax Value Calcs'!I34 -> 13600 | J35: ='Tax Value Calcs'!K34 -> 6800 | K35: =I35/J35 -> 2 | L35: ='Tax Value Calcs'!M34 -> 9950 | M35: ='Tax Value Calcs'!O34 -> 6800
A36: =A37+1 -> 2020 | B36: ='Tax Value Calcs'!D23 -> 24800 | C36: ='Tax Value Calcs'!F23 -> 12400 | D36: =B36/C36 -> 2 | E36: ='Tax Value Calcs'!H23 -> 18600 | F36: ='Tax Value Calcs'!J23 -> 12400 | H36: =H37+1 -> 2020 | I36: ='Tax Value Calcs'!I35 -> 13400 | J36: ='Tax Value Calcs'!K35 -> 6700 | K36: =I36/J36 -> 2 | L36: ='Tax Value Calcs'!M35 -> 9850 | M36: ='Tax Value Calcs'!O35 -> 6700
A37: =A38+1 -> 2019 | B37: ='Tax Value Calcs'!D24 -> 24400 | C37: ='Tax Value Calcs'!F24 -> 12200 | D37: =B37/C37 -> 2 | E37: ='Tax Value Calcs'!H24 -> 18350 | F37: ='Tax Value Calcs'!J24 -> 12200 | H37: =H38+1 -> 2019 | I37: ='Tax Value Calcs'!I36 -> 13200 | J37: ='Tax Value Calcs'!K36 -> 6600 | K37: =I37/J37 -> 2 | L37: ='Tax Value Calcs'!M36 -> 9700 | M37: ='Tax Value Calcs'!O36 -> 6600
A38: =A39+1 -> 2018 | B38: ='Tax Value Calcs'!D25 -> 24000 | C38: ='Tax Value Calcs'!F25 -> 12000 | D38: =B38/C38 -> 2 | E38: ='Tax Value Calcs'!M37 -> 9500 | F38: ='Tax Value Calcs'!O37 -> 6450 | H38: =H39+1 -> 2018 | I38: ='Tax Value Calcs'!I37 -> 12900 | J38: ='Tax Value Calcs'!K37 -> 6450 | K38: =I38/J38 -> 2 | L38: ='Tax Value Calcs'!M37 -> 9500 | M38: ='Tax Value Calcs'!O37 -> 6450
A39: =A40+1 -> 2017 | B39: ='Tax Value Calcs'!I38 -> 12700 | C39: ='Tax Value Calcs'!K38 -> 6350 | D39: =B39/C39 -> 2 | E39: ='Tax Value Calcs'!M38 -> 9350 | F39: ='Tax Value Calcs'!O38 -> 6350 | H39: 2017 | I39: ='Tax Value Calcs'!I38 -> 12700 | J39: ='Tax Value Calcs'!K38 -> 6350 | K39: =I39/J39 -> 2 | L39: ='Tax Value Calcs'!M38 -> 9350 | M39: ='Tax Value Calcs'!O38 -> 6350
A40: =A41+1 -> 2016 | B40: ='Tax Value Calcs'!I39 -> 12600 | C40: ='Tax Value Calcs'!K39 -> 6300 | D40: =B40/C40 -> 2 | E40: ='Tax Value Calcs'!M39 -> 9300 | F40: ='Tax Value Calcs'!O39 -> 6300
A41: =A42+1 -> 2015 | B41: ='Tax Value Calcs'!I40 -> 12600 | C41: ='Tax Value Calcs'!K40 -> 6300 | D41: =B41/C41 -> 2 | E41: ='Tax Value Calcs'!M40 -> 9250 | F41: ='Tax Value Calcs'!O40 -> 6300
A42: =A43+1 -> 2014 | B42: ='Tax Value Calcs'!I41 -> 12400 | C42: ='Tax Value Calcs'!K41 -> 6200 | D42: =B42/C42 -> 2 | E42: ='Tax Value Calcs'!M41 -> 9100 | F42: ='Tax Value Calcs'!O41 -> 6200
...

Sheet Tax Value Calcs
A1: CPI Indexing Calculations for Income Tax Values
A2: These calculations are used to index IRS base numbers from the internal revenue code to future years.
A4: Color Coding:
A5: Green | B5: Base value that is indexed to get subsequent year values.
A6: Red | B6: Future values based upon a CPI value (3% in the examples) picked out of the air.
A9: Cumulative CPI for TCJA Sunset (for 2026 Sunset)
A10: Year | B10: Cumulative CPI
A11: =A12+1 -> 2022 | B11: ='CPI-U & C-CPI-U Calcs'!G14 -> 1.096417
A12: =A13+1 -> 2021 | B12: ='CPI-U & C-CPI-U Calcs'!G15 -> 1.0644825
A13: =A14+1 -> 2020 | B13: ='CPI-U & C-CPI-U Calcs'!G16 -> 1.0528385
A14: =A15+1 -> 2019 | B14: ='CPI-U & C-CPI-U Calcs'!G17 -> 1.0367586
A15: =A16+1 -> 2018 | B15: ='CPI-U & C-CPI-U Calcs'!G18 -> 1.016499
A16: 2017 | B16: ='CPI-U & C-CPI-U Calcs'!G19 -> 1
A19: Standard Deduction *
A20: Tax Year | B20: Prev Year Cum CPI | C20: Joint 1 | D20: Joint (rounded) | E20: Single | F20: Single (rounded) | G20: Head of Household | H20: Household (rounded) | I20: Separate | J20: Separate (rounded)
A21: =A22+1 -> 2022 | B21: ='CPI-U & C-CPI-U Calcs'!$F14 -> 1.0786208 | C21: =E21*2 -> 25886.899 | D21: =+TRUNC(C21/100)*100 -> 25800 | E21: =E$25*$B21 -> 12943.449 | F21: =+TRUNC(E21/50)*50 -> 12900 | G21: =G$25*$B21 -> 19415.174 | H21: =+TRUNC(G21/50)*50 -> 19400 | I21: =I$25*$B21 -> 12943.449 | J21: =+TRUNC(I21/50)*50 -> 12900
A22: =A23+1 -> 2021 | B22: ='CPI-U & C-CPI-U Calcs'!$F15 -> 1.0472046 | C22: =E22*2 -> 25132.911 | D22: =+TRUNC(C22/100)*100 -> 25100 | E22: =E$25*$B22 -> 12566.456 | F22: =+TRUNC(E22/50)*50 -> 12550 | G22: =G$25*$B22 -> 18849.684 | H22: =+TRUNC(G22/50)*50 -> 18800 | I22: =I$25*$B22 -> 12566.456 | J22: =+TRUNC(I22/50)*50 -> 12550
A23: =A24+1 -> 2020 | B23: ='CPI-U & C-CPI-U Calcs'!$F16 -> 1.0357497 | C23: =E23*2 -> 24857.992 | D23: =+TRUNC(C23/100)*100 -> 24800 | E23: =E$25*$B23 -> 12428.996 | F23: =+TRUNC(E23/50)*50 -> 12400 | G23: =G$25*$B23 -> 18643.494 | H23: =+TRUNC(G23/50)*50 -> 18600 | I23: =I$25*$B23 -> 12428.996 | J23: =+TRUNC(I23/50)*50 -> 12400
A24: =A25+1 -> 2019 | B24: ='CPI-U & C-CPI-U Calcs'!$F17 -> 1.0199308 | C24: =E24*2 -> 24478.339 | D24: =+TRUNC(C24/100)*100 -> 24400 | E24: =E$25*$B24 -> 12239.169 | F24: =+TRUNC(E24/50)*50 -> 12200 | G24: =G$25*$B24 -> 18358.754 | H24: =+TRUNC(G24/50)*50 -> 18350 | I24: =I$25*$B24 -> 12239.169 | J24: =+TRUNC(I24/50)*50 -> 12200
A25: 2018 | B25: ='CPI-U & C-CPI-U Calcs'!$F18 -> 1 | C25: =E25*2 -> 24000 | D25: =+TRUNC(C25/50)*50 -> 24000 | E25: 12000 | F25: =+TRUNC(E25/50)*50 -> 12000 | G25: 18000 | H25: =+TRUNC(G25/50)*50 -> 18000 | I25: 12000 | J25: =+TRUNC(I25/50)*50 -> 12000
A26: NOTE: Rounding is down to the nearest $100 for joint, $50 single or separate, and $25 for married filing separtely
A27: * Values during the TCJA period starting 2019 that are not current are likely to be wrong to due later restatement of C-CPI-U values.
A28: 1 Joint value calculated as 2X rounded value for single
A31: Standard Deduction - Additional Over Age 65 | H31: Standard Deduction - Basic (for 2026 Sunset)
A32: Tax Year | B32: Prev Year Cum CPI | C32: Joint Age 65 or Older† | D32: Joint (rounded)† | E32: Single Age 65 or Older | F32: Single (rounded) | H32: Joint† | I32: Joint (rounded) | J32: Single | K32: Single (rounded) | L32: Head of Household | M32: Household (rounded) | N32: Separate | O32: Separate (rounded)
A33: =A34+1 -> 2022 | B33: ='CPI-U & C-CPI-U Calcs'!$S14 -> 2.3365871 | C33: =C$67*$B33 -> 1401.9523 | D33: =+TRUNC(C33/50)*50 -> 1400 | E33: =E$67*$B33 -> 1752.4403 | F33: =+TRUNC(E33/50)*50 -> 1750 | H33: =J33*2 -> 14019.523 | I33: =+TRUNC(H33/100)*100 -> 14000 | J33: =J$67*$B33 -> 7009.7613 | K33: =+TRUNC(J33/50)*50 -> 7000 | L33: =L$67*$B33 -> 10280.983 | M33: =+TRUNC(L33/50)*50 -> 10250 | N33: =N$67*$B33 -> 7009.7613 | O33: =+TRUNC(N33/50)*50 -> 7000
A34: =A35+1 -> 2021 | B34: ='CPI-U & C-CPI-U Calcs'!$S15 -> 2.2685312 | C34: =C$67*$B34 -> 1361.1187 | D34: =+TRUNC(C34/50)*50 -> 1350 | E34: =E$67*$B34 -> 1701.3984 | F34: =+TRUNC(E34/50)*50 -> 1700 | H34: =J34*2 -> 13611.187 | I34: =+TRUNC(H34/100)*100 -> 13600 | J34: =J$67*$B34 -> 6805.5935 | K34: =+TRUNC(J34/50)*50 -> 6800 | L34: =L$67*$B34 -> 9981.5371 | M34: =+TRUNC(L34/50)*50 -> 9950 | N34: =N$67*$B34 -> 6805.5935 | O34: =+TRUNC(N34/50)*50 -> 6800
A35: =A36+1 -> 2020 | B35: ='CPI-U & C-CPI-U Calcs'!$S16 -> 2.2437165 | C35: =C$67*$B35 -> 1346.2299 | D35: =+TRUNC(C35/50)*50 -> 1300 | E35: =E$67*$B35 -> 1682.7874 | F35: =+TRUNC(E35/50)*50 -> 1650 | H35: =J35*2 -> 13462.299 | I35: =+TRUNC(H35/100)*100 -> 13400 | J35: =J$67*$B35 -> 6731.1496 | K35: =+TRUNC(J35/50)*50 -> 6700 | L35: =L$67*$B35 -> 9872.3527 | M35: =+TRUNC(L35/50)*50 -> 9850 | N35: =N$67*$B35 -> 6731.1496 | O35: =+TRUNC(N35/50)*50 -> 6700
A36: =A37+1 -> 2019 | B36: ='CPI-U & C-CPI-U Calcs'!$S17 -> 2.2094485 | C36: =C$67*$B36 -> 1325.6691 | D36: =+TRUNC(C36/50)*50 -> 1300 | E36: =E$67*$B36 -> 1657.0864 | F36: =+TRUNC(E36/50)*50 -> 1650 | H36: =J36*2 -> 13256.691 | I36: =+TRUNC(H36/100)*100 -> 13200 | J36: =J$67*$B36 -> 6628.3456 | K36: =+TRUNC(J36/50)*50 -> 6600 | L36: =L$67*$B36 -> 9721.5735 | M36: =+TRUNC(L36/50)*50 -> 9700 | N36: =N$67*$B36 -> 6628.3456 | O36: =+TRUNC(N36/50)*50 -> 6600
A37: 2018 | B37: ='CPI-U & C-CPI-U Calcs'!$S18 -> 2.166273 | C37: =C$67*$B37 -> 1299.7638 | D37: =+TRUNC(C37/50)*50 -> 1250 | E37: =E$67*$B37 -> 1624.7048 | F37: =+TRUNC(E37/50)*50 -> 1600 | H37: =J37*2 -> 12997.638 | I37: =+TRUNC(H37/100)*100 -> 12900 | J37: =J$67*$B37 -> 6498.819 | K37: =+TRUNC(J37/50)*50 -> 6450 | L37: =L$67*$B37 -> 9531.6012 | M37: =+TRUNC(L37/50)*50 -> 9500 | N37: =N$67*$B37 -> 6498.819 | O37: =+TRUNC(N37/50)*50 -> 6450
A38: =A39+1 -> 2017 | B38: ='CPI-U & C-CPI-U Calcs'!$S19 -> 2.1311118 | C38: =C$67*$B38 -> 1278.6671 | D38: =+TRUNC(C38/50)*50 -> 1250 | E38: =E$67*$B38 -> 1598.3338 | F38: =+TRUNC(E38/50)*50 -> 1550 | H38: =J38*2 -> 12786.671 | I38: =+TRUNC(H38/100)*100 -> 12700 | J38: =J$67*$B38 -> 6393.3353 | K38: =+TRUNC(J38/50)*50 -> 6350 | L38: =L$67*$B38 -> 9376.8918 | M38: =+TRUNC(L38/50)*50 -> 9350 | N38: =N$67*$B38 -> 6393.3353 | O38: =+TRUNC(N38/50)*50 -> 6350
A39: =A40+1 -> 2016 | B39: ='CPI-U & C-CPI-U Calcs'!$S20 -> 2.1141442 | C39: =C$67*$B39 -> 1268.4865 | D39: =+TRUNC(C39/50)*50 -> 1250 | E39: =E$67*$B39 -> 1585.6082 | F39: =+TRUNC(E39/50)*50 -> 1550 | H39: =J39*2 -> 12684.865 | I39: =+TRUNC(H39/100)*100 -> 12600 | J39: =J$67*$B39 -> 6342.4327 | K39: =+TRUNC(J39/50)*50 -> 6300 | L39: =L$67*$B39 -> 9302.2346 | M39: =+TRUNC(L39/50)*50 -> 9300 | N39: =N$67*$B39 -> 6342.4327 | O39: =+TRUNC(N39/50)*50 -> 6300
A40: =A41+1 -> 2015 | B40: ='CPI-U & C-CPI-U Calcs'!$S21 -> 2.1046435 | C40: =C$67*$B40 -> 1262.7861 | D40: =+TRUNC(C40/50)*50 -> 1250 | E40: =E$67*$B40 -> 1578.4827 | F40: =+TRUNC(E40/50)*50 -> 1550 | H40: =J40*2 -> 12627.861 | I40: =+TRUNC(H40/100)*100 -> 12600 | J40: =J$67*$B40 -> 6313.9306 | K40: =+TRUNC(J40/50)*50 -> 6300 | L40: =L$67*$B40 -> 9260.4316 | M40: =+TRUNC(L40/50)*50 -> 9250 | N40: =N$67*$B40 -> 6313.9306 | O40: =+TRUNC(N40/50)*50 -> 6300
A41: =A42+1 -> 2014 | B41: ='CPI-U & C-CPI-U Calcs'!$S22 -> 2.0718991 | C41: =C$67*$B41 -> 1243.1395 | D41: =+TRUNC(C41/50)*50 -> 1200 | E41: =E$67*$B41 -> 1553.9243 | F41: =+TRUNC(E41/50)*50 -> 1550 | H41: =J41*2 -> 12431.395 | I41: =+TRUNC(H41/100)*100 -> 12400 | J41: =J$67*$B41 -> 6215.6973 | K41: =+TRUNC(J41/50)*50 -> 6200 | L41: =L$67*$B41 -> 9116.356 | M41: =+TRUNC(L41/50)*50 -> 9100 | N41: =N$67*$B41 -> 6215.6973 | O41: =+TRUNC(N41/50)*50 -> 6200
A42: =A43+1 -> 2013 | B42: ='CPI-U & C-CPI-U Calcs'!$S23 -> 2.0373515 | C42: =C$67*$B42 -> 1222.4109 | D42: =+TRUNC(C42/50)*50 -> 1200 | E42: =E$67*$B42 -> 1528.0137 | F42: =+TRUNC(E42/50)*50 -> 1500 | H42: =J42*2 -> 12224.109 | I42: =+TRUNC(H42/100)*100 -> 12200 | J42: =J$67*$B42 -> 6112.0546 | K42: =+TRUNC(J42/50)*50 -> 6100 | L42: =L$67*$B42 -> 8964.3468 | M42: =+TRUNC(L42/50)*50 -> 8950 | N42: =N$67*$B42 -> 6112.0546 | O42: =+TRUNC(N42/50)*50 -> 6100
A43: =A44+1 -> 2012 | B43: ='CPI-U & C-CPI-U Calcs'!$S24 -> 1.9863 | C43: =C$67*$B43 -> 1191.78 | D43: =+TRUNC(C43/50)*50 -> 1150 | E43: =E$67*$B43 -> 1489.725 | F43: =+TRUNC(E43/50)*50 -> 1450 | H43: =J43*2 -> 11917.8 | I43: =+TRUNC(H43/100)*100 -> 11900 | J43: =J$67*$B43 -> 5958.9001 | K43: =+TRUNC(J43/50)*50 -> 5950 | L43: =L$67*$B43 -> 8739.7202 | M43: =+TRUNC(L43/50)*50 -> 8700 | N43: =N$67*$B43 -> 5958.9001 | O43: =+TRUNC(N43/50)*50 -> 5950
A44: =A45+1 -> 2011 | B44: ='CPI-U & C-CPI-U Calcs'!$S25 -> 1.9392462 | C44: =C$67*$B44 -> 1163.5477 | D44: =+TRUNC(C44/50)*50 -> 1150 | E44: =E$67*$B44 -> 1454.4346 | F44: =+TRUNC(E44/50)*50 -> 1450 | H44: =J44*2 -> 11635.477 | I44: =+TRUNC(H44/100)*100 -> 11600 | J44: =J$67*$B44 -> 5817.7385 | K44: =+TRUNC(J44/50)*50 -> 5800 | L44: =L$67*$B44 -> 8532.6831 | M44: =+TRUNC(L44/50)*50 -> 8500 | N44: =N$67*$B44 -> 5817.7385 | O44: =+TRUNC(N44/50)*50 -> 5800
A45: =A46+1 -> 2010 | B45: ='CPI-U & C-CPI-U Calcs'!$S26 -> 1.9110195 | C45: =C$67*$B45 -> 1146.6117 | D45: =+TRUNC(C45/50)*50 -> 1100 | E45: =E$67*$B45 -> 1433.2646 | F45: =+TRUNC(E45/50)*50 -> 1400 | H45: =J45*2 -> 11466.117 | I45: =+TRUNC(H45/100)*100 -> 11400 | J45: =J$67*$B45 -> 5733.0585 | K45: =+TRUNC(J45/50)*50 -> 5700 | L45: =L$67*$B45 -> 8408.4858 | M45: =+TRUNC(L45/50)*50 -> 8400 | N45: =N$67*$B45 -> 5733.0585 | O45: =+TRUNC(N45/50)*50 -> 5700
A46: =A47+1 -> 2009 | B46: ='CPI-U & C-CPI-U Calcs'!$S27 -> 1.9074713 | C46: =C$67*$B46 -> 1144.4828 | D46: =+TRUNC(C46/50)*50 -> 1100 | E46: =E$67*$B46 -> 1430.6035 | F46: =+TRUNC(E46/50)*50 -> 1400 | H46: =J46*2 -> 11444.828 | I46: =+TRUNC(H46/100)*100 -> 11400 | J46: =J$67*$B46 -> 5722.414 | K46: =+TRUNC(J46/50)*50 -> 5700 | L46: =L$67*$B46 -> 8392.8739 | M46: =+TRUNC(L46/50)*50 -> 8350 | N46: =N$67*$B46 -> 5722.414 | O46: =+TRUNC(N46/50)*50 -> 5700
A47: =A48+1 -> 2008 | B47: ='CPI-U & C-CPI-U Calcs'!$S28 -> 1.829491 | C47: =C$67*$B47 -> 1097.6946 | D47: =+TRUNC(C47/50)*50 -> 1050 | E47: =E$67*$B47 -> 1372.1182 | F47: =+TRUNC(E47/50)*50 -> 1350 | H47: =J47*2 -> 10976.946 | I47: =+TRUNC(H47/100)*100 -> 10900 | J47: =J$67*$B47 -> 5488.473 | K47: =+TRUNC(J47/50)*50 -> 5450 | L47: =L$67*$B47 -> 8049.7604 | M47: =+TRUNC(L47/50)*50 -> 8000 | N47: =N$67*$B47 -> 5488.473 | O47: =+TRUNC(N47/50)*50 -> 5450
...

Sheet Tax Brackets
A1: Income Tax Brackets
A2: NOTE: All values based upon "taxable year".
A3: These are IRS published values. The raw values that we use are under the tabs showing tax law extension.
A4: *** See "2022-2026 IRS Updates" sheet for complete updated 2022-2026 values from IRS Rev. Procs. 2021-45 through 2025-32 and OBBBA 2025 ***
A6: Income Tax Brackets
A7: 2021 Tax Rate Schedules
A8: Schedule Y-1 - Joint | D8: Schedule X - Single | G8: Schedule Z - Head of Household | J8: Schedule Y-2 - Separate | M8: Schedule for Trusts
A9: From | B9: To | C9: Tax Rate | D9: From | E9: To | F9: Rate | G9: From | H9: To | I9: Tax Rate | J9: From | K9: To | L9: Tax Rate | M9: From | N9: To | O9: Tax Rate
A10: 0 | B10: ='Tax Bracket Calcs'!F$22 -> 19900 | C10: 0.1 | D10: 0 | E10: ='Tax Bracket Calcs'!M$22 -> 9950 | F10: 0.1 | G10: 0 | H10: ='Tax Bracket Calcs'!T$22 -> 14200 | I10: 0.1 | J10: 0 | K10: ='Tax Bracket Calcs'!AA$22 -> 9950 | L10: 0.1 | M10: 0 | N10: ='Tax Bracket Calcs'!AH$22 -> 2650 | O10: 0.1
A11: =B10 -> 19900 | B11: ='Tax Bracket Calcs'!G$22 -> 81050 | C11: 0.12 | D11: =E10 -> 9950 | E11: ='Tax Bracket Calcs'!N$22 -> 40525 | F11: 0.12 | G11: =H10 -> 14200 | H11: ='Tax Bracket Calcs'!U$22 -> 54200 | I11: 0.12 | J11: =K10 -> 9950 | K11: ='Tax Bracket Calcs'!AB$22 -> 40525 | L11: 0.12 | M11: 0 | N11: ='Tax Bracket Calcs'!AI$22 -> unused | O11: 0.12
A12: =B11 -> 81050 | B12: ='Tax Bracket Calcs'!H$22 -> 172750 | C12: 0.22 | D12: =E11 -> 40525 | E12: ='Tax Bracket Calcs'!O$22 -> 86375 | F12: 0.22 | G12: =H11 -> 54200 | H12: ='Tax Bracket Calcs'!V$22 -> 86350 | I12: 0.22 | J12: =K11 -> 40525 | K12: ='Tax Bracket Calcs'!AC$22 -> 86375 | L12: 0.22 | M12: =N11 -> unused | N12: ='Tax Bracket Calcs'!AJ$22 -> unused | O12: 0.22
A13: =B12 -> 172750 | B13: ='Tax Bracket Calcs'!I$22 -> 329850 | C13: 0.24 | D13: =E12 -> 86375 | E13: ='Tax Bracket Calcs'!P$22 -> 164925 | F13: 0.24 | G13: =H12 -> 86350 | H13: ='Tax Bracket Calcs'!W$22 -> 164900 | I13: 0.24 | J13: =K12 -> 86375 | K13: ='Tax Bracket Calcs'!AD$22 -> 164925 | L13: 0.24 | M13: =N12 -> unused | N13: ='Tax Bracket Calcs'!AK$22 -> 9550 | O13: 0.24
A14: =B13 -> 329850 | B14: ='Tax Bracket Calcs'!J$22 -> 418850 | C14: 0.32 | D14: =E13 -> 164925 | E14: ='Tax Bracket Calcs'!Q$22 -> 209425 | F14: 0.32 | G14: =H13 -> 164900 | H14: ='Tax Bracket Calcs'!X$22 -> 209400 | I14: 0.32 | J14: =K13 -> 164925 | K14: ='Tax Bracket Calcs'!AE$22 -> 209425 | L14: 0.32 | M14: =N13 -> 9550 | N14: ='Tax Bracket Calcs'!AL$22 -> unused | O14: 0.32
A15: =B14 -> 418850 | B15: ='Tax Bracket Calcs'!K$22 -> 628300 | C15: 0.35 | D15: =E14 -> 209425 | E15: ='Tax Bracket Calcs'!R$22 -> 523600 | F15: 0.35 | G15: =H14 -> 209400 | H15: ='Tax Bracket Calcs'!Y$22 -> 523600 | I15: 0.35 | J15: =K14 -> 209425 | K15: ='Tax Bracket Calcs'!AF$22 -> 314150 | L15: 0.35 | M15: =N14 -> unused | N15: ='Tax Bracket Calcs'!AM$22 -> 13050 | O15: 0.35
A16: =B15 -> 628300 | B16: above | C16: 0.37 | D16: =E15 -> 523600 | E16: above | F16: 0.37 | G16: =H15 -> 523600 | H16: above | I16: 0.37 | J16: =K15 -> 314150 | K16: above | L16: 0.37 | M16: =N15 -> 13050 | N16: above | O16: 0.37
A19: 2020 Tax Rate Schedules
A20: Schedule Y-1 - Joint | D20: Schedule X - Single | G20: Schedule Z - Head of Household | J20: Schedule Y-2 - Separate | M20: Schedule for Trusts
A21: From | B21: To | C21: Tax Rate | D21: From | E21: To | F21: Rate | G21: From | H21: To | I21: Tax Rate | J21: From | K21: To | L21: Tax Rate | M21: From | N21: To | O21: Tax Rate
A22: 0 | B22: ='Tax Bracket Calcs'!F$23 -> 19700 | C22: 0.1 | D22: 0 | E22: ='Tax Bracket Calcs'!M$23 -> 9850 | F22: 0.1 | G22: 0 | H22: ='Tax Bracket Calcs'!T$23 -> 14050 | I22: 0.1 | J22: 0 | K22: ='Tax Bracket Calcs'!AA$23 -> 9850 | L22: 0.1 | M22: 0 | N22: ='Tax Bracket Calcs'!AH$23 -> 2600 | O22: 0.1
A23: =B22 -> 19700 | B23: ='Tax Bracket Calcs'!G$23 -> 80150 | C23: 0.12 | D23: =E22 -> 9850 | E23: ='Tax Bracket Calcs'!N$23 -> 40075 | F23: 0.12 | G23: =H22 -> 14050 | H23: ='Tax Bracket Calcs'!U$23 -> 53650 | I23: 0.12 | J23: =K22 -> 9850 | K23: ='Tax Bracket Calcs'!AB$23 -> 40075 | L23: 0.12 | M23: 0 | N23: ='Tax Bracket Calcs'!AI$23 -> unused | O23: 0.12
A24: =B23 -> 80150 | B24: ='Tax Bracket Calcs'!H$23 -> 170850 | C24: 0.22 | D24: =E23 -> 40075 | E24: ='Tax Bracket Calcs'!O$23 -> 85425 | F24: 0.22 | G24: =H23 -> 53650 | H24: ='Tax Bracket Calcs'!V$23 -> 85400 | I24: 0.22 | J24: =K23 -> 40075 | K24: ='Tax Bracket Calcs'!AC$23 -> 85425 | L24: 0.22 | M24: =N23 -> unused | N24: ='Tax Bracket Calcs'!AJ$23 -> unused | O24: 0.22
A25: =B24 -> 170850 | B25: ='Tax Bracket Calcs'!I$23 -> 326250 | C25: 0.24 | D25: =E24 -> 85425 | E25: ='Tax Bracket Calcs'!P$23 -> 163125 | F25: 0.24 | G25: =H24 -> 85400 | H25: ='Tax Bracket Calcs'!W$23 -> 163100 | I25: 0.24 | J25: =K24 -> 85425 | K25: ='Tax Bracket Calcs'!AD$23 -> 163125 | L25: 0.24 | M25: =N24 -> unused | N25: ='Tax Bracket Calcs'!AK$23 -> 9450 | O25: 0.24
A26: =B25 -> 326250 | B26: ='Tax Bracket Calcs'!J$23 -> 414250 | C26: 0.32 | D26: =E25 -> 163125 | E26: ='Tax Bracket Calcs'!Q$23 -> 207125 | F26: 0.32 | G26: =H25 -> 163100 | H26: ='Tax Bracket Calcs'!X$23 -> 207100 | I26: 0.32 | J26: =K25 -> 163125 | K26: ='Tax Bracket Calcs'!AE$23 -> 207125 | L26: 0.32 | M26: =N25 -> 9450 | N26: ='Tax Bracket Calcs'!AL$23 -> unused | O26: 0.32
A27: =B26 -> 414250 | B27: ='Tax Bracket Calcs'!K$23 -> 621400 | C27: 0.35 | D27: =E26 -> 207125 | E27: ='Tax Bracket Calcs'!R$23 -> 517850 | F27: 0.35 | G27: =H26 -> 207100 | H27: ='Tax Bracket Calcs'!Y$23 -> 517850 | I27: 0.35 | J27: =K26 -> 207125 | K27: ='Tax Bracket Calcs'!AF$23 -> 310700 | L27: 0.35 | M27: =N26 -> unused | N27: ='Tax Bracket Calcs'!AM$23 -> 12900 | O27: 0.35
A28: =B27 -> 621400 | B28: above | C28: 0.37 | D28: =E27 -> 517850 | E28: above | F28: 0.37 | G28: =H27 -> 517850 | H28: above | I28: 0.37 | J28: =K27 -> 310700 | K28: above | L28: 0.37 | M28: =N27 -> 12900 | N28: above | O28: 0.37
A31: 2019 Tax Rate Schedules
A32: Schedule Y-1 - Joint | D32: Schedule X - Single | G32: Schedule Z - Head of Household | J32: Schedule Y-2 - Separate | M32: Schedule for Trusts
A33: From | B33: To | C33: Tax Rate | D33: From | E33: To | F33: Rate | G33: From | H33: To | I33: Tax Rate | J33: From | K33: To | L33: Tax Rate | M33: From | N33: To | O33: Tax Rate
A34: 0 | B34: ='Tax Bracket Calcs'!F$24 -> 19400 | C34: 0.1 | D34: 0 | E34: ='Tax Bracket Calcs'!M$24 -> 9700 | F34: 0.1 | G34: 0 | H34: ='Tax Bracket Calcs'!T$24 -> 13850 | I34: 0.1 | J34: 0 | K34: ='Tax Bracket Calcs'!AA$24 -> 9700 | L34: 0.1 | M34: 0 | N34: ='Tax Bracket Calcs'!AH$24 -> 2600 | O34: 0.1
A35: =B34 -> 19400 | B35: ='Tax Bracket Calcs'!G$24 -> 78900 | C35: 0.12 | D35: =E34 -> 9700 | E35: ='Tax Bracket Calcs'!N$24 -> 39450 | F35: 0.12 | G35: =H34 -> 13850 | H35: ='Tax Bracket Calcs'!U$24 -> 52800 | I35: 0.12 | J35: =K34 -> 9700 | K35: ='Tax Bracket Calcs'!AB$24 -> 39450 | L35: 0.12 | M35: 0 | N35: ='Tax Bracket Calcs'!AI$24 -> unused | O35: 0.12
A36: =B35 -> 78900 | B36: ='Tax Bracket Calcs'!H$24 -> 168250 | C36: 0.22 | D36: =E35 -> 39450 | E36: ='Tax Bracket Calcs'!O$24 -> 84125 | F36: 0.22 | G36: =H35 -> 52800 | H36: ='Tax Bracket Calcs'!V$24 -> 84100 | I36: 0.22 | J36: =K35 -> 39450 | K36: ='Tax Bracket Calcs'!AC$24 -> 84125 | L36: 0.22 | M36: =N35 -> unused | N36: ='Tax Bracket Calcs'!AJ$24 -> unused | O36: 0.22
A37: =B36 -> 168250 | B37: ='Tax Bracket Calcs'!I$24 -> 321250 | C37: 0.24 | D37: =E36 -> 84125 | E37: ='Tax Bracket Calcs'!P$24 -> 160625 | F37: 0.24 | G37: =H36 -> 84100 | H37: ='Tax Bracket Calcs'!W$24 -> 160600 | I37: 0.24 | J37: =K36 -> 84125 | K37: ='Tax Bracket Calcs'!AD$24 -> 160625 | L37: 0.24 | M37: =N36 -> unused | N37: ='Tax Bracket Calcs'!AK$24 -> 9300 | O37: 0.24
A38: =B37 -> 321250 | B38: ='Tax Bracket Calcs'!J$24 -> 407950 | C38: 0.32 | D38: =E37 -> 160625 | E38: ='Tax Bracket Calcs'!Q$24 -> 203975 | F38: 0.32 | G38: =H37 -> 160600 | H38: ='Tax Bracket Calcs'!X$24 -> 203950 | I38: 0.32 | J38: =K37 -> 160625 | K38: ='Tax Bracket Calcs'!AE$24 -> 203975 | L38: 0.32 | M38: =N37 -> 9300 | N38: ='Tax Bracket Calcs'!AL$24 -> unused | O38: 0.32
A39: =B38 -> 407950 | B39: ='Tax Bracket Calcs'!K$24 -> 611950 | C39: 0.35 | D39: =E38 -> 203975 | E39: ='Tax Bracket Calcs'!R$24 -> 509950 | F39: 0.35 | G39: =H38 -> 203950 | H39: ='Tax Bracket Calcs'!Y$24 -> 509950 | I39: 0.35 | J39: =K38 -> 203975 | K39: ='Tax Bracket Calcs'!AF$24 -> 305975 | L39: 0.35 | M39: =N38 -> unused | N39: ='Tax Bracket Calcs'!AM$24 -> 12700 | O39: 0.35
A40: =B39 -> 611950 | B40: above | C40: 0.37 | D40: =E39 -> 509950 | E40: above | F40: 0.37 | G40: =H39 -> 509950 | H40: above | I40: 0.37 | J40: =K39 -> 305975 | K40: above | L40: 0.37 | M40: =N39 -> 12700 | N40: above | O40: 0.37
A43: 2018 Tax Rate Schedules
A44: Schedule Y-1 - Joint | D44: Schedule X - Single | G44: Schedule Z - Head of Household | J44: Schedule Y-2 - Separate | M44: Schedule for Trusts
A45: From | B45: To | C45: Tax Rate | D45: From | E45: To | F45: Rate | G45: From | H45: To | I45: Tax Rate | J45: From | K45: To | L45: Tax Rate | M45: From | N45: To | O45: Tax Rate
A46: 0 | B46: ='Tax Bracket Calcs'!F$25 -> 19050 | C46: 0.1 | D46: 0 | E46: ='Tax Bracket Calcs'!M$25 -> 9525 | F46: 0.1 | G46: 0 | H46: ='Tax Bracket Calcs'!T$25 -> 13600 | I46: 0.1 | J46: 0 | K46: ='Tax Bracket Calcs'!AA$25 -> 9525 | L46: 0.1 | M46: 0 | N46: ='Tax Bracket Calcs'!AH$25 -> 2550 | O46: 0.1
A47: =B46 -> 19050 | B47: ='Tax Bracket Calcs'!G$25 -> 77400 | C47: 0.12 | D47: =E46 -> 9525 | E47: ='Tax Bracket Calcs'!N$25 -> 38700 | F47: 0.15 | G47: =H46 -> 13600 | H47: ='Tax Bracket Calcs'!U$25 -> 51800 | I47: 0.15 | J47: =K46 -> 9525 | K47: ='Tax Bracket Calcs'!AB$25 -> 38700 | L47: 0.15 | M47: 0 | N47: ='Tax Bracket Calcs'!AI$25 -> unused | O47: 0.15
...

Sheet Tax Bracket Calcs
A1: CPI Indexing Calculations for Income & Capital Gains Tax Brackets
A2: These calculations are used to index IRS base numbers from the internal revenue code to future years.
A4: Color Coding:
A5: Green | B5: Base value that is indexed to get subsequent year values.
A6: Red | B6: Future values based upon a CPI value (3% in the examples) picked out of the air.
A7: Gray | B7: Values maintained to support the sunset provisions in 2026.
A9: Income Tax Brackets
F10: Married Filing Jointly | M10: Single | T10: Head of Household | AA10: Married Filing Separately | AH10: Trusts & Estates
A11: Tax Year | E11: CPI (base year 2018) | F11: 10% Bracket | G11: 12% Bracket | H11: 22% Bracket | I11: 24% Bracket | J11: 32% Bracket | K11: 35% Bracket | L11: 37% Bracket | M11: 10% Bracket | N11: 12% Bracket | O11: 22% Bracket | P11: 24% Bracket | Q11: 32% Bracket | R11: 35% Bracket | S11: 37% Bracket | T11: 10% Bracket | U11: 12% Bracket | V11: 22% Bracket | W11: 24% Bracket | X11: 32% Bracket | Y11: 35% Bracket | Z11: 37% Bracket | AA11: 10% Bracket | AB11: 12% Bracket | AC11: 22% Bracket | AD11: 24% Bracket | AE11: 32% Bracket | AF11: 35% Bracket | AG11: 37% Bracket | AH11: 10% Bracket | AI11: 12% Bracket | AJ11: 22% Bracket | AK11: 24% Bracket | AL11: 32% Bracket | AM11: 35% Bracket | AN11: 37% Bracket
A12: =A13+1 -> 2022 | E12: ='CPI-U & C-CPI-U Calcs'!$F14 -> 1.0786208 | F12: =F$16*$E12 -> 20547.726 | G12: =G$16*$E12 -> 83485.249 | H12: =H$16*$E12 -> 177972.43 | I12: =I$16*$E12 -> 339765.55 | J12: =J$16*$E12 -> 431448.31 | K12: =K$16*$E12 -> 647172.47 | L12: excess | M12: =M$16*$E12 -> 10273.863 | N12: =N$16*$E12 -> 41742.624 | O12: =O$16*$E12 -> 88986.215 | P12: =P$16*$E12 -> 169882.77 | Q12: =Q$16*$E12 -> 215724.16 | R12: =R$16*$E12 -> 539310.39 | S12: excess | T12: =T$16*$E12 -> 14669.243 | U12: =U$16*$E12 -> 55872.557 | V12: =V$16*$E12 -> 88986.215 | W12: =W$16*$E12 -> 169882.77 | X12: =X$16*$E12 -> 215724.16 | Y12: =Y$16*$E12 -> 539310.39 | Z12: excess | AA12: =AA$16*$E12 -> 10273.863 | AB12: =AB$16*$E12 -> 41742.624 | AC12: =AC$16*$E12 -> 88986.215 | AD12: =AD$16*$E12 -> 169882.77 | AE12: =AE$16*$E12 -> 215724.16 | AF12: =AF$16*$E12 -> 323586.24 | AG12: excess | AH12: =AH$16*$E12 -> 2750.483 | AI12: unused | AJ12: unused | AK12: =AK$16*$E12 -> 9869.3802 | AL12: unused | AM12: =AM$16*$E12 -> 13482.76 | AN12: excess
A13: =A14+1 -> 2021 | E13: ='CPI-U & C-CPI-U Calcs'!$F15 -> 1.0472046 | F13: =F$16*$E13 -> 19949.248 | G13: =G$16*$E13 -> 81053.639 | H13: =H$16*$E13 -> 172788.77 | I13: =I$16*$E13 -> 329869.46 | J13: =J$16*$E13 -> 418881.86 | K13: =K$16*$E13 -> 628322.79 | L13: excess | M13: =M$16*$E13 -> 9974.6242 | N13: =N$16*$E13 -> 40526.82 | O13: =O$16*$E13 -> 86394.383 | P13: =P$16*$E13 -> 164934.73 | Q13: =Q$16*$E13 -> 209440.93 | R13: =R$16*$E13 -> 523602.32 | S13: excess | T13: =T$16*$E13 -> 14241.983 | U13: =U$16*$E13 -> 54245.201 | V13: =V$16*$E13 -> 86394.383 | W13: =W$16*$E13 -> 164934.73 | X13: =X$16*$E13 -> 209440.93 | Y13: =Y$16*$E13 -> 523602.32 | Z13: excess | AA13: =AA$16*$E13 -> 9974.6242 | AB13: =AB$16*$E13 -> 40526.82 | AC13: =AC$16*$E13 -> 86394.383 | AD13: =AD$16*$E13 -> 164934.73 | AE13: =AE$16*$E13 -> 209440.93 | AF13: =AF$16*$E13 -> 314161.39 | AG13: excess | AH13: =AH$16*$E13 -> 2670.3718 | AI13: unused | AJ13: unused | AK13: =AK$16*$E13 -> 9581.9225 | AL13: unused | AM13: =AM$16*$E13 -> 13090.058 | AN13: excess
A14: =A15+1 -> 2020 | E14: ='CPI-U & C-CPI-U Calcs'!$F16 -> 1.0357497 | F14: =F$16*$E14 -> 19731.031 | G14: =G$16*$E14 -> 80167.024 | H14: =H$16*$E14 -> 170898.69 | I14: =I$16*$E14 -> 326261.14 | J14: =J$16*$E14 -> 414299.86 | K14: =K$16*$E14 -> 621449.8 | L14: excess | M14: =M$16*$E14 -> 9865.5155 | N14: =N$16*$E14 -> 40083.512 | O14: =O$16*$E14 -> 85449.347 | P14: =P$16*$E14 -> 163130.57 | Q14: =Q$16*$E14 -> 207149.93 | R14: =R$16*$E14 -> 517874.83 | S14: excess | T14: =T$16*$E14 -> 14086.195 | U14: =U$16*$E14 -> 53651.832 | V14: =V$16*$E14 -> 85449.347 | W14: =W$16*$E14 -> 163130.57 | X14: =X$16*$E14 -> 207149.93 | Y14: =Y$16*$E14 -> 517874.83 | Z14: excess | AA14: =AA$16*$E14 -> 9865.5155 | AB14: =AB$16*$E14 -> 40083.512 | AC14: =AC$16*$E14 -> 85449.347 | AD14: =AD$16*$E14 -> 163130.57 | AE14: =AE$16*$E14 -> 207149.93 | AF14: =AF$16*$E14 -> 310724.9 | AG14: excess | AH14: =AH$16*$E14 -> 2641.1616 | AI14: unused | AJ14: unused | AK14: =AK$16*$E14 -> 9477.1094 | AL14: unused | AM14: =AM$16*$E14 -> 12946.871 | AN14: excess
A15: =A16+1 -> 2019 | E15: ='CPI-U & C-CPI-U Calcs'!$F17 -> 1.0199308 | F15: =F$16*$E15 -> 19429.681 | G15: =G$16*$E15 -> 78942.643 | H15: =H$16*$E15 -> 168288.58 | I15: =I$16*$E15 -> 321278.2 | J15: =J$16*$E15 -> 407972.31 | K15: =K$16*$E15 -> 611958.47 | L15: excess | M15: =M$16*$E15 -> 9714.8407 | N15: =N$16*$E15 -> 39471.321 | O15: =O$16*$E15 -> 84144.29 | P15: =P$16*$E15 -> 160639.1 | Q15: =Q$16*$E15 -> 203986.16 | R15: =R$16*$E15 -> 509965.39 | S15: excess | T15: =T$16*$E15 -> 13871.059 | U15: =U$16*$E15 -> 52832.415 | V15: =V$16*$E15 -> 84144.29 | W15: =W$16*$E15 -> 160639.1 | X15: =X$16*$E15 -> 203986.16 | Y15: =Y$16*$E15 -> 509965.39 | Z15: excess | AA15: =AA$16*$E15 -> 9714.8407 | AB15: =AB$16*$E15 -> 39471.321 | AC15: =AC$16*$E15 -> 84144.29 | AD15: =AD$16*$E15 -> 160639.1 | AE15: =AE$16*$E15 -> 203986.16 | AF15: =AF$16*$E15 -> 305979.23 | AG15: excess | AH15: =AH$16*$E15 -> 2600.8235 | AI15: unused | AJ15: unused | AK15: =AK$16*$E15 -> 9332.3667 | AL15: unused | AM15: =AM$16*$E15 -> 12749.135 | AN15: excess
A16: 2018 | E16: ='CPI-U & C-CPI-U Calcs'!$F18 -> 1 | F16: 19050 | G16: 77400 | H16: 165000 | I16: 315000 | J16: 400000 | K16: 600000 | L16: excess | M16: 9525 | N16: 38700 | O16: 82500 | P16: 157500 | Q16: 200000 | R16: 500000 | S16: excess | T16: 13600 | U16: 51800 | V16: 82500 | W16: 157500 | X16: 200000 | Y16: 500000 | Z16: excess | AA16: 9525 | AB16: 38700 | AC16: 82500 | AD16: 157500 | AE16: 200000 | AF16: 300000 | AG16: excess | AH16: 2550 | AI16: unused | AJ16: unused | AK16: 9150 | AL16: unused | AM16: 12500 | AN16: excess
AA17: * NOTE: Actual law sets this to 50% of the rounded Joint amount.
A18: Rounded Income Tax Brackets
F19: Married Filing Jointly | M19: Single | T19: Head of Household | AA19: Married Filing Separately | AH19: Trusts & Estates
A20: Tax Year | F20: 10% Bracket | G20: 12% Bracket | H20: 22% Bracket | I20: 24% Bracket | J20: 32% Bracket | K20: 35% Bracket | L20: 37% Bracket | M20: 10% Bracket | N20: 12% Bracket | O20: 22% Bracket | P20: 24% Bracket | Q20: 32% Bracket | R20: 35% Bracket | S20: 37% Bracket | T20: 10% Bracket | U20: 12% Bracket | V20: 22% Bracket | W20: 24% Bracket | X20: 32% Bracket | Y20: 35% Bracket | Z20: 37% Bracket | AA20: 10% Bracket | AB20: 12% Bracket | AC20: 22% Bracket | AD20: 24% Bracket | AE20: 32% Bracket | AF20: 35% Bracket | AG20: 37% Bracket | AH20: 10% Bracket | AI20: 12% Bracket | AJ20: 22% Bracket | AK20: 24% Bracket | AL20: 32% Bracket | AM20: 35% Bracket | AN20: 37% Bracket
A21: =A22+1 -> 2022 | F21: =TRUNC(F12/50)*50 -> 20500 | G21: =TRUNC(G12/50)*50 -> 83450 | H21: =TRUNC(H12/50)*50 -> 177950 | I21: =TRUNC(I12/50)*50 -> 339750 | J21: =TRUNC(J12/50)*50 -> 431400 | K21: =TRUNC(K12/50)*50 -> 647150 | L21: excess | M21: =TRUNC(M12/25)*25 -> 10250 | N21: =TRUNC(N12/25)*25 -> 41725 | O21: =TRUNC(O12/25)*25 -> 88975 | P21: =TRUNC(P12/25)*25 -> 169875 | Q21: =TRUNC(Q12/25)*25 -> 215700 | R21: =TRUNC(R12/25)*25 -> 539300 | S21: excess | T21: =TRUNC(T12/50)*50 -> 14650 | U21: =TRUNC(U12/50)*50 -> 55850 | V21: =TRUNC(V12/50)*50 -> 88950 | W21: =TRUNC(W12/50)*50 -> 169850 | X21: =TRUNC(X12/50)*50 -> 215700 | Y21: =TRUNC(Y12/50)*50 -> 539300 | Z21: excess | AA21: =TRUNC(AA12/25)*25 -> 10250 | AB21: =TRUNC(AB12/50)*50 -> 41700 | AC21: =TRUNC(AC12/25)*25 -> 88975 | AD21: =TRUNC(AD12/25)*25 -> 169875 | AE21: =TRUNC(AE12/25)*25 -> 215700 | AF21: =TRUNC(AF12/25)*25 -> 323575 | AG21: excess | AH21: =TRUNC(AH12/50)*50 -> 2750 | AI21: =AI12 -> unused | AJ21: =AJ12 -> unused | AK21: =TRUNC(AK12/50)*50 -> 9850 | AL21: =AL12 -> unused | AM21: =TRUNC(AM12/50)*50 -> 13450 | AN21: =AN12 -> excess
A22: =A23+1 -> 2021 | F22: =TRUNC(F13/50)*50 -> 19900 | G22: =TRUNC(G13/50)*50 -> 81050 | H22: =TRUNC(H13/50)*50 -> 172750 | I22: =TRUNC(I13/50)*50 -> 329850 | J22: =TRUNC(J13/50)*50 -> 418850 | K22: =TRUNC(K13/50)*50 -> 628300 | L22: excess | M22: =TRUNC(M13/25)*25 -> 9950 | N22: =TRUNC(N13/25)*25 -> 40525 | O22: =TRUNC(O13/25)*25 -> 86375 | P22: =TRUNC(P13/25)*25 -> 164925 | Q22: =TRUNC(Q13/25)*25 -> 209425 | R22: =TRUNC(R13/25)*25 -> 523600 | S22: excess | T22: =TRUNC(T13/50)*50 -> 14200 | U22: =TRUNC(U13/50)*50 -> 54200 | V22: =TRUNC(V13/50)*50 -> 86350 | W22: =TRUNC(W13/50)*50 -> 164900 | X22: =TRUNC(X13/50)*50 -> 209400 | Y22: =TRUNC(Y13/50)*50 -> 523600 | Z22: excess | AA22: =TRUNC(AA13/25)*25 -> 9950 | AB22: =TRUNC(AB13/25)*25 -> 40525 | AC22: =TRUNC(AC13/25)*25 -> 86375 | AD22: =TRUNC(AD13/25)*25 -> 164925 | AE22: =TRUNC(AE13/25)*25 -> 209425 | AF22: =TRUNC(AF13/25)*25 -> 314150 | AG22: excess | AH22: =TRUNC(AH13/50)*50 -> 2650 | AI22: =AI13 -> unused | AJ22: =AJ13 -> unused | AK22: =TRUNC(AK13/50)*50 -> 9550 | AL22: =AL13 -> unused | AM22: =TRUNC(AM13/50)*50 -> 13050 | AN22: =AN13 -> excess
A23: =A24+1 -> 2020 | F23: =TRUNC(F14/50)*50 -> 19700 | G23: =TRUNC(G14/50)*50 -> 80150 | H23: =TRUNC(H14/50)*50 -> 170850 | I23: =TRUNC(I14/50)*50 -> 326250 | J23: =TRUNC(J14/50)*50 -> 414250 | K23: =TRUNC(K14/50)*50 -> 621400 | L23: excess | M23: =TRUNC(M14/25)*25 -> 9850 | N23: =TRUNC(N14/25)*25 -> 40075 | O23: =TRUNC(O14/25)*25 -> 85425 | P23: =TRUNC(P14/25)*25 -> 163125 | Q23: =TRUNC(Q14/25)*25 -> 207125 | R23: =TRUNC(R14/25)*25 -> 517850 | S23: excess | T23: =TRUNC(T14/50)*50 -> 14050 | U23: =TRUNC(U14/50)*50 -> 53650 | V23: =TRUNC(V14/50)*50 -> 85400 | W23: =TRUNC(W14/50)*50 -> 163100 | X23: =TRUNC(X14/50)*50 -> 207100 | Y23: =TRUNC(Y14/50)*50 -> 517850 | Z23: excess | AA23: =TRUNC(AA14/25)*25 -> 9850 | AB23: =TRUNC(AB14/25)*25 -> 40075 | AC23: =TRUNC(AC14/25)*25 -> 85425 | AD23: =TRUNC(AD14/25)*25 -> 163125 | AE23: =TRUNC(AE14/25)*25 -> 207125 | AF23: =TRUNC(AF14/25)*25 -> 310700 | AG23: excess | AH23: =TRUNC(AH14/50)*50 -> 2600 | AI23: =AI14 -> unused | AJ23: =AJ14 -> unused | AK23: =TRUNC(AK14/50)*50 -> 9450 | AL23: =AL14 -> unused | AM23: =TRUNC(AM14/50)*50 -> 12900 | AN23: =AN14 -> excess
A24: =A25+1 -> 2019 | F24: =TRUNC(F15/50)*50 -> 19400 | G24: =TRUNC(G15/50)*50 -> 78900 | H24: =TRUNC(H15/50)*50 -> 168250 | I24: =TRUNC(I15/50)*50 -> 321250 | J24: =TRUNC(J15/50)*50 -> 407950 | K24: =TRUNC(K15/50)*50 -> 611950 | L24: excess | M24: =TRUNC(M15/25)*25 -> 9700 | N24: =TRUNC(N15/25)*25 -> 39450 | O24: =TRUNC(O15/25)*25 -> 84125 | P24: =TRUNC(P15/25)*25 -> 160625 | Q24: =TRUNC(Q15/25)*25 -> 203975 | R24: =TRUNC(R15/25)*25 -> 509950 | S24: excess | T24: =TRUNC(T15/50)*50 -> 13850 | U24: =TRUNC(U15/50)*50 -> 52800 | V24: =TRUNC(V15/50)*50 -> 84100 | W24: =TRUNC(W15/50)*50 -> 160600 | X24: =TRUNC(X15/50)*50 -> 203950 | Y24: =TRUNC(Y15/50)*50 -> 509950 | Z24: excess | AA24: =TRUNC(AA15/25)*25 -> 9700 | AB24: =TRUNC(AB15/25)*25 -> 39450 | AC24: =TRUNC(AC15/25)*25 -> 84125 | AD24: =TRUNC(AD15/25)*25 -> 160625 | AE24: =TRUNC(AE15/25)*25 -> 203975 | AF24: =TRUNC(AF15/25)*25 -> 305975 | AG24: excess | AH24: =TRUNC(AH15/50)*50 -> 2600 | AI24: =AI15 -> unused | AJ24: =AJ15 -> unused | AK24: =TRUNC(AK15/50)*50 -> 9300 | AL24: =AL15 -> unused | AM24: =TRUNC(AM15/50)*50 -> 12700 | AN24: =AN15 -> excess
A25: 2018 | F25: =TRUNC(F16/50)*50 -> 19050 | G25: =TRUNC(G16/50)*50 -> 77400 | H25: =TRUNC(H16/50)*50 -> 165000 | I25: =TRUNC(I16/50)*50 -> 315000 | J25: =TRUNC(J16/50)*50 -> 400000 | K25: =TRUNC(K16/50)*50 -> 600000 | L25: excess | M25: =TRUNC(M16/25)*25 -> 9525 | N25: =TRUNC(N16/25)*25 -> 38700 | O25: =TRUNC(O16/25)*25 -> 82500 | P25: =TRUNC(P16/25)*25 -> 157500 | Q25: =TRUNC(Q16/25)*25 -> 200000 | R25: =TRUNC(R16/25)*25 -> 500000 | S25: excess | T25: =TRUNC(T16/50)*50 -> 13600 | U25: =TRUNC(U16/50)*50 -> 51800 | V25: =TRUNC(V16/50)*50 -> 82500 | W25: =TRUNC(W16/50)*50 -> 157500 | X25: =TRUNC(X16/50)*50 -> 200000 | Y25: =TRUNC(Y16/50)*50 -> 500000 | Z25: excess | AA25: =TRUNC(AA16/25)*25 -> 9525 | AB25: =TRUNC(AB16/25)*25 -> 38700 | AC25: =TRUNC(AC16/25)*25 -> 82500 | AD25: =TRUNC(AD16/25)*25 -> 157500 | AE25: =TRUNC(AE16/25)*25 -> 200000 | AF25: =TRUNC(AF16/25)*25 -> 300000 | AG25: excess | AH25: =TRUNC(AH16/50)*50 -> 2550 | AI25: =AI16 -> unused | AJ25: =AJ16 -> unused | AK25: =TRUNC(AK16/50)*50 -> 9150 | AL25: =AL16 -> unused | AM25: =AM16 -> 12500 | AN25: =AN16 -> excess
A29: Income Tax Brackets (for 2026 Sunset)
F30: Married Filing Jointly | M30: Single | T30: Head of Household | AA30: Married Filing Separately | AH30: Trusts & Estates
A31: Tax Year | B31: CPI (base year 2013) | C31: CPI (base year 2003) | D31: CPI (base year 1993) | E31: CPI (base year 1994) | F31: 10% Bracket | G31: 15% Bracket | H31: 25% Bracket | I31: 28% Bracket | J31: 33% Bracket | K31: 35% Bracket | L31: 39.6% Bracket | M31: 10% Bracket | N31: 15% Bracket | O31: 25% Bracket | P31: 28% Bracket | Q31: 33% Bracket | R31: 35% Bracket | S31: 39.6% Bracket | T31: 10% Bracket | U31: 15% Bracket | V31: 25% Bracket | W31: 28% Bracket | X31: 33% Bracket | Y31: 35% Bracket | Z31: 39.6% Bracket | AA31: 10% Bracket | AB31: 15% Bracket | AC31: 25% Bracket | AD31: 28% Bracket | AE31: 33% Bracket | AF31: 35% Bracket | AG31: 39.6% Bracket | AH31: 10% Bracket | AI31: 15% Bracket | AJ31: 25% Bracket | AK31: 28% Bracket | AL31: 33% Bracket | AM31: 35% Bracket | AN31: 39.6% Bracket
A32: =A33+1 -> 2022 | B32: ='CPI-U & C-CPI-U Calcs'!$H14 -> 1.1468748 | C32: ='CPI-U & C-CPI-U Calcs'!$L14 -> 1.46444 | D32: ='CPI-U & C-CPI-U Calcs'!$P14 -> 1.8834537 | E32: ='CPI-U & C-CPI-U Calcs'!$O14 -> 1.8275454 | F32: =F$51*$C32 -> 20502.16 | G32: =G$61*$D32 -> 83248.655 | H32: =H$61*$D32 -> 167909.9 | I32: =I$60*$E32 -> 255856.35 | J32: =J$60*$E32 -> 456886.35 | K32: =K$41*$B32 -> 516093.65 | L32: excess | M32: =M$51*$C32 -> 10251.08 | N32: =N$61*$D32 -> 41624.328 | O32: =O$61*$D32 -> 100764.78 | P32: =P$60*$E32 -> 210167.72 | Q32: =Q$60*$E32 -> 456886.35 | R32: =R$41*$B32 -> 458749.91 | S32: excess | T32: =T$51*$C32 -> 14644.4 | U32: =U$61*$D32 -> 55750.231 | V32: =V$61*$D32 -> 143895.87 | W32: =W$60*$E32 -> 233012.04 | X32: =X$60*$E32 -> 456886.35 | Y32: =Y$41*$B32 -> 487421.78 | Z32: excess | AA32: =AA$51*$C32 -> 10251.08 | AB32: =AB$61*$D32 -> 41624.328 | AC32: =AC$61*$D32 -> 83954.951 | AD32: =AD$60*$E32 -> 127928.18 | AE32: =AE$60*$E32 -> 228443.17 | AF32: =AF$41*$B32 -> 258046.82 | AG32: excess | AH32: 0 | AI32: =AI$61*$D32 -> 2825.1806 | AJ32: =AJ$61*$D32 -> 6592.0881 | AK32: =AK$60*$E32 -> 10051.5 | AL32: =AL$60*$E32 -> 13706.59 | AM32: =AM33 -> unused | AN32: excess
A33: =A34+1 -> 2021 | B33: ='CPI-U & C-CPI-U Calcs'!$H15 -> 1.1134707 | C33: ='CPI-U & C-CPI-U Calcs'!$L15 -> 1.4217864 | D33: ='CPI-U & C-CPI-U Calcs'!$P15 -> 1.8285959 | E33: ='CPI-U & C-CPI-U Calcs'!$O15 -> 1.7743159 | F33: =F$51*$C33 -> 19905.009 | G33: =G$61*$D33 -> 80823.937 | H33: =H$61*$D33 -> 163019.32 | I33: =I$60*$E33 -> 248404.23 | J33: =J$60*$E33 -> 443578.98 | K33: =K$41*$B33 -> 501061.8 | L33: excess | M33: =M$51*$C33 -> 9952.5046 | N33: =N$61*$D33 -> 40411.969 | O33: =O$61*$D33 -> 97829.879 | P33: =P$60*$E33 -> 204046.33 | Q33: =Q$60*$E33 -> 443578.98 | R33: =R$41*$B33 -> 445388.26 | S33: excess | T33: =T$51*$C33 -> 14217.864 | U33: =U$61*$D33 -> 54126.438 | V33: =V$61*$D33 -> 139704.72 | W33: =W$60*$E33 -> 226225.28 | X33: =X$60*$E33 -> 443578.98 | Y33: =Y$41*$B33 -> 473225.03 | Z33: excess | AA33: =AA$51*$C33 -> 9952.5046 | AB33: =AB$61*$D33 -> 40411.969 | AC33: =AC$61*$D33 -> 81509.661 | AD33: =AD$60*$E33 -> 124202.11 | AE33: =AE$60*$E33 -> 221789.49 | AF33: =AF$41*$B33 -> 250530.9 | AG33: excess | AH33: 0 | AI33: =AI$61*$D33 -> 2742.8938 | AJ33: =AJ$61*$D33 -> 6400.0855 | AK33: =AK$60*$E33 -> 9758.7375 | AL33: =AL$60*$E33 -> 13307.369 | AM33: =AM34 -> unused | AN33: excess
A34: =A35+1 -> 2020 | B34: ='CPI-U & C-CPI-U Calcs'!$H16 -> 1.1012908 | C34: ='CPI-U & C-CPI-U Calcs'!$L16 -> 1.406234 | D34: ='CPI-U & C-CPI-U Calcs'!$P16 -> 1.8085935 | E34: ='CPI-U & C-CPI-U Calcs'!$O16 -> 1.7549073 | F34: =F$51*$C34 -> 19687.276 | G34: =G$61*$D34 -> 79939.834 | H34: =H$61*$D34 -> 161236.11 | I34: =I$60*$E34 -> 245687.03 | J34: =J$60*$E34 -> 438726.83 | K34: =K$41*$B34 -> 495580.86 | L34: excess | M34: =M$51*$C34 -> 9843.6379 | N34: =N$61*$D34 -> 39969.917 | O34: =O$61*$D34 -> 96759.754 | P34: =P$60*$E34 -> 201814.34 | Q34: =Q$60*$E34 -> 438726.83 | R34: =R$41*$B34 -> 440516.32 | S34: excess | T34: =T$51*$C34 -> 14062.34 | U34: =U$61*$D34 -> 53534.368 | V34: =V$61*$D34 -> 138176.55 | W34: =W$60*$E34 -> 223750.68 | X34: =X$60*$E34 -> 438726.83 | Y34: =Y$41*$B34 -> 468048.59 | Z34: excess | AA34: =AA$51*$C34 -> 9843.6379 | AB34: =AB$61*$D34 -> 39969.917 | AC34: =AC$61*$D34 -> 80618.057 | AD34: =AD$60*$E34 -> 122843.51 | AE34: =AE$60*$E34 -> 219363.42 | AF34: =AF$41*$B34 -> 247790.43 | AG34: excess | AH34: 0 | AI34: =AI$61*$D34 -> 2712.8903 | AJ34: =AJ$61*$D34 -> 6330.0774 | AK34: =AK$60*$E34 -> 9651.9903 | AL34: =AL$60*$E34 -> 13161.805 | AM34: =AM35 -> unused | AN34: excess
A35: =A36+1 -> 2019 | B35: ='CPI-U & C-CPI-U Calcs'!$H17 -> 1.0844709 | C35: ='CPI-U & C-CPI-U Calcs'!$L17 -> 1.3847567 | D35: ='CPI-U & C-CPI-U Calcs'!$P17 -> 1.7809711 | E35: ='CPI-U & C-CPI-U Calcs'!$O17 -> 1.7281048 | F35: =F$51*$C35 -> 19386.594 | G35: =G$61*$D35 -> 78718.923 | H35: =H$61*$D35 -> 158773.57 | I35: =I$60*$E35 -> 241934.68 | J35: =J$60*$E35 -> 432026.21 | K35: =K$41*$B35 -> 488011.92 | L35: excess | M35: =M$51*$C35 -> 9693.2972 | N35: =N$61*$D35 -> 39359.461 | O35: =O$61*$D35 -> 95281.954 | P35: =P$60*$E35 -> 198732.06 | Q35: =Q$60*$E35 -> 432026.21 | R35: =R$41*$B35 -> 433788.37 | S35: excess | T35: =T$51*$C35 -> 13847.567 | U35: =U$61*$D35 -> 52716.745 | V35: =V$61*$D35 -> 136066.19 | W35: =W$60*$E35 -> 220333.37 | X35: =X$60*$E35 -> 432026.21 | Y35: =Y$41*$B35 -> 460900.15 | Z35: excess | AA35: =AA$51*$C35 -> 9693.2972 | AB35: =AB$61*$D35 -> 39359.461 | AC35: =AC$61*$D35 -> 79386.787 | AD35: =AD$60*$E35 -> 120967.34 | AE35: =AE$60*$E35 -> 216013.11 | AF35: =AF$41*$B35 -> 244005.96 | AG35: excess | AH35: 0 | AI35: =AI$61*$D35 -> 2671.4567 | AJ35: =AJ$61*$D35 -> 6233.3989 | AK35: =AK$60*$E35 -> 9504.5766 | AL35: =AL$60*$E35 -> 12960.786 | AM35: =AM36 -> unused | AN35: excess
A36: =A37+1 -> 2018 | B36: ='CPI-U & C-CPI-U Calcs'!$H18 -> 1.063279 | C36: ='CPI-U & C-CPI-U Calcs'!$L18 -> 1.3576968 | D36: ='CPI-U & C-CPI-U Calcs'!$P18 -> 1.7461686 | E36: ='CPI-U & C-CPI-U Calcs'!$O18 -> 1.6943354 | F36: =F$51*$C36 -> 19007.755 | G36: =G$61*$D36 -> 77180.652 | H36: =H$61*$D36 -> 155670.93 | I36: =I$60*$E36 -> 237206.96 | J36: =J$60*$E36 -> 423583.85 | K36: =K$41*$B36 -> 478475.53 | L36: excess | M36: =M$51*$C36 -> 9503.8775 | N36: =N$61*$D36 -> 38590.326 | O36: =O$61*$D36 -> 93420.02 | P36: =P$60*$E36 -> 194848.57 | Q36: =Q$60*$E36 -> 423583.85 | R36: =R$41*$B36 -> 425311.58 | S36: excess | T36: =T$51*$C36 -> 13576.968 | U36: =U$61*$D36 -> 51686.59 | V36: =V$61*$D36 -> 133407.28 | W36: =W$60*$E36 -> 216027.76 | X36: =X$60*$E36 -> 423583.85 | Y36: =Y$41*$B36 -> 451893.55 | Z36: excess | AA36: =AA$51*$C36 -> 9503.8775 | AB36: =AB$61*$D36 -> 38590.326 | AC36: =AC$61*$D36 -> 77835.465 | AD36: =AD$60*$E36 -> 118603.48 | AE36: =AE$60*$E36 -> 211791.93 | AF36: =AF$41*$B36 -> 239237.76 | AG36: excess | AH36: 0 | AI36: =AI$61*$D36 -> 2619.2529 | AJ36: =AJ$61*$D36 -> 6111.5901 | AK36: =AK$60*$E36 -> 9318.8448 | AL36: =AL$60*$E36 -> 12707.516 | AM36: =AM37 -> unused | AN36: excess
A37: =A38+1 -> 2017 | B37: ='CPI-U & C-CPI-U Calcs'!$H19 -> 1.0460206 | C37: ='CPI-U & C-CPI-U Calcs'!$L19 -> 1.3356597 | D37: ='CPI-U & C-CPI-U Calcs'!$P19 -> 1.7178262 | E37: ='CPI-U & C-CPI-U Calcs'!$O19 -> 1.6668343 | F37: =F$51*$C37 -> 18699.236 | G37: =G$61*$D37 -> 75927.917 | H37: =H$61*$D37 -> 153144.2 | I37: =I$60*$E37 -> 233356.8 | J37: =J$60*$E37 -> 416708.57 | K37: =K$41*$B37 -> 470709.29 | L37: excess | M37: =M$51*$C37 -> 9349.618 | N37: =N$61*$D37 -> 37963.958 | O37: =O$61*$D37 -> 91903.7 | P37: =P$60*$E37 -> 191685.94 | Q37: =Q$60*$E37 -> 416708.57 | R37: =R$41*$B37 -> 418408.26 | S37: excess | T37: =T$51*$C37 -> 13356.597 | U37: =U$61*$D37 -> 50847.654 | V37: =V$61*$D37 -> 131241.92 | W37: =W$60*$E37 -> 212521.37 | X37: =X$60*$E37 -> 416708.57 | Y37: =Y$41*$B37 -> 444558.77 | Z37: excess | AA37: =AA$51*$C37 -> 9349.618 | AB37: =AB$61*$D37 -> 37963.958 | AC37: =AC$61*$D37 -> 76572.101 | AD37: =AD$60*$E37 -> 116678.4 | AE37: =AE$60*$E37 -> 208354.29 | AF37: =AF$41*$B37 -> 235354.65 | AG37: excess | AH37: 0 | AI37: =AI$61*$D37 -> 2576.7392 | AJ37: =AJ$61*$D37 -> 6012.3916 | AK37: =AK$60*$E37 -> 9167.5886 | AL37: =AL$60*$E37 -> 12501.257 | AM37: =AM38 -> unused | AN37: excess
A38: =A39+1 -> 2016 | B38: ='CPI-U & C-CPI-U Calcs'!$H20 -> 1.0376924 | C38: ='CPI-U & C-CPI-U Calcs'!$L20 -> 1.3250254 | D38: ='CPI-U & C-CPI-U Calcs'!$P20 -> 1.7041491 | E38: ='CPI-U & C-CPI-U Calcs'!$O20 -> 1.6535632 | F38: =F$51*$C38 -> 18550.356 | G38: =G$61*$D38 -> 75323.391 | H38: =H$61*$D38 -> 151924.89 | I38: =I$60*$E38 -> 231498.85 | J38: =J$60*$E38 -> 413390.81 | K38: =K$41*$B38 -> 466961.58 | L38: excess | M38: =M$51*$C38 -> 9275.1779 | N38: =N$61*$D38 -> 37661.696 | O38: =O$61*$D38 -> 91171.978 | P38: =P$60*$E38 -> 190159.77 | Q38: =Q$60*$E38 -> 413390.81 | R38: =R$41*$B38 -> 415076.96 | S38: excess | T38: =T$51*$C38 -> 13250.254 | U38: =U$61*$D38 -> 50442.814 | V38: =V$61*$D38 -> 130196.99 | W38: =W$60*$E38 -> 210829.31 | X38: =X$60*$E38 -> 413390.81 | Y38: =Y$41*$B38 -> 441019.27 | Z38: excess | AA38: =AA$51*$C38 -> 9275.1779 | AB38: =AB$61*$D38 -> 37661.696 | AC38: =AC$61*$D38 -> 75962.447 | AD38: =AD$60*$E38 -> 115749.43 | AE38: =AE$60*$E38 -> 206695.4 | AF38: =AF$41*$B38 -> 233480.79 | AG38: excess | AH38: 0 | AI38: =AI$61*$D38 -> 2556.2237 | AJ38: =AJ$61*$D38 -> 5964.5219 | AK38: =AK$60*$E38 -> 9094.5978 | AL38: =AL$60*$E38 -> 12401.724 | AM38: =AM39 -> unused | AN38: excess
A39: =A40+1 -> 2015 | B39: ='CPI-U & C-CPI-U Calcs'!$H21 -> 1.0330292 | C39: ='CPI-U & C-CPI-U Calcs'!$L21 -> 1.3190709 | D39: ='CPI-U & C-CPI-U Calcs'!$P21 -> 1.6964909 | E39: ='CPI-U & C-CPI-U Calcs'!$O21 -> 1.6461324 | F39: =F$51*$C39 -> 18466.993 | G39: =G$61*$D39 -> 74984.898 | H39: =H$61*$D39 -> 151242.16 | I39: =I$60*$E39 -> 230458.53 | J39: =J$60*$E39 -> 411533.09 | K39: =K$41*$B39 -> 464863.12 | L39: excess | M39: =M$51*$C39 -> 9233.4966 | N39: =N$61*$D39 -> 37492.449 | O39: =O$61*$D39 -> 90762.264 | P39: =P$60*$E39 -> 189305.22 | Q39: =Q$60*$E39 -> 411533.09 | R39: =R$41*$B39 -> 413211.66 | S39: excess | T39: =T$51*$C39 -> 13190.709 | U39: =U$61*$D39 -> 50216.131 | V39: =V$61*$D39 -> 129611.91 | W39: =W$60*$E39 -> 209881.88 | X39: =X$60*$E39 -> 411533.09 | Y39: =Y$41*$B39 -> 439037.39 | Z39: excess | AA39: =AA$51*$C39 -> 9233.4966 | AB39: =AB$61*$D39 -> 37492.449 | AC39: =AC$61*$D39 -> 75621.082 | AD39: =AD$60*$E39 -> 115229.26 | AE39: =AE$60*$E39 -> 205766.54 | AF39: =AF$41*$B39 -> 232431.56 | AG39: excess | AH39: 0 | AI39: =AI$61*$D39 -> 2544.7364 | AJ39: =AJ$61*$D39 -> 5937.7182 | AK39: =AK$60*$E39 -> 9053.728 | AL39: =AL$60*$E39 -> 12345.993 | AM39: =AM40 -> unused | AN39: excess
A40: =A41+1 -> 2014 | B40: ='CPI-U & C-CPI-U Calcs'!$H22 -> 1.0169571 | C40: ='CPI-U & C-CPI-U Calcs'!$L22 -> 1.2985486 | D40: ='CPI-U & C-CPI-U Calcs'!$P22 -> 1.6700966 | E40: ='CPI-U & C-CPI-U Calcs'!$O22 -> 1.6205215 | F40: =F$51*$C40 -> 18179.68 | G40: =G$61*$D40 -> 73818.269 | H40: =H$61*$D40 -> 148889.11 | I40: =I$60*$E40 -> 226873.01 | J40: =J$60*$E40 -> 405130.38 | K40: =K$41*$B40 -> 457630.69 | L40: excess | M40: =M$51*$C40 -> 9089.84 | N40: =N$61*$D40 -> 36909.134 | O40: =O$61*$D40 -> 89350.167 | P40: =P$60*$E40 -> 186359.97 | Q40: =Q$60*$E40 -> 405130.38 | R40: =R$41*$B40 -> 406782.84 | S40: excess | T40: =T$51*$C40 -> 12985.486 | U40: =U$61*$D40 -> 49434.859 | V40: =V$61*$D40 -> 127595.38 | W40: =W$60*$E40 -> 206616.49 | X40: =X$60*$E40 -> 405130.38 | Y40: =Y$41*$B40 -> 432206.76 | Z40: excess | AA40: =AA$51*$C40 -> 9089.84 | AB40: =AB$61*$D40 -> 36909.134 | AC40: =AC$61*$D40 -> 74444.555 | AD40: =AD$60*$E40 -> 113436.51 | AE40: =AE$60*$E40 -> 202565.19 | AF40: =AF$41*$B40 -> 228815.35 | AG40: excess | AH40: 0 | AI40: =AI$61*$D40 -> 2505.1449 | AJ40: =AJ$61*$D40 -> 5845.338 | AK40: =AK$60*$E40 -> 8912.8683 | AL40: =AL$60*$E40 -> 12153.911 | AM40: =AM41 -> unused | AN40: excess
A41: =A42+1 -> 2013 | B41: ='CPI-U & C-CPI-U Calcs'!$H23 -> 1 | C41: ='CPI-U & C-CPI-U Calcs'!$L23 -> 1.2768961 | D41: ='CPI-U & C-CPI-U Calcs'!$P23 -> 1.6422488 | E41: ='CPI-U & C-CPI-U Calcs'!$O23 -> 1.5935004 | F41: =F$51*$C41 -> 17876.546 | G41: =G$61*$D41 -> 72587.398 | H41: =H$61*$D41 -> 146406.48 | I41: =I$60*$E41 -> 223090.05 | J41: =J$60*$E41 -> 398375.09 | K41: 450000 | L41: excess | M41: =M$51*$C41 -> 8938.2729 | N41: =N$61*$D41 -> 36293.699 | O41: =O$61*$D41 -> 87860.312 | P41: =P$60*$E41 -> 183252.54 | Q41: =Q$60*$E41 -> 398375.09 | R41: 400000 | S41: excess | T41: =T$51*$C41 -> 12768.961 | U41: =U$61*$D41 -> 48610.565 | V41: =V$61*$D41 -> 125467.81 | W41: =W$60*$E41 -> 203171.3 | X41: =X$60*$E41 -> 398375.09 | Y41: 425000 | Z41: excess | AA41: =AA$51*$C41 -> 8938.2729 | AB41: =AB$61*$D41 -> 36293.699 | AC41: =AC$61*$D41 -> 73203.241 | AD41: =AD$60*$E41 -> 111545.03 | AE41: =AE$60*$E41 -> 199187.55 | AF41: 225000 | AG41: excess | AH41: 0 | AI41: =AI$61*$D41 -> 2463.3732 | AJ41: =AJ$61*$D41 -> 5747.8709 | AK41: =AK$60*$E41 -> 8764.2521 | AL41: =AL$60*$E41 -> 11951.253 | AM41: unused | AN41: excess
A42: =A43+1 -> 2012 | C42: ='CPI-U & C-CPI-U Calcs'!$L24 -> 1.2449 | D42: ='CPI-U & C-CPI-U Calcs'!$P24 -> 1.6010977 | E42: ='CPI-U & C-CPI-U Calcs'!$O24 -> 1.5535708 | F42: =F$51*$C42 -> 17428.599 | G42: =G$61*$D42 -> 70768.519 | H42: =H$61*$D42 -> 142737.86 | I42: =I$60*$E42 -> 217499.91 | J42: =J$60*$E42 -> 388392.7 | L42: excess | M42: =M$51*$C42 -> 8714.2997 | N42: =N$61*$D42 -> 35384.259 | O42: =O$61*$D42 -> 85658.728 | P42: =P$60*$E42 -> 178660.64 | Q42: =Q$60*$E42 -> 388392.7 | S42: excess | T42: =T$51*$C42 -> 12449 | U42: =U$61*$D42 -> 47392.492 | V42: =V$61*$D42 -> 122323.87 | W42: =W$60*$E42 -> 198080.28 | X42: =X$60*$E42 -> 388392.7 | Z42: excess | AA42: =AA$51*$C42 -> 8714.2997 | AB42: =AB$61*$D42 -> 35384.259 | AC42: =AC$61*$D42 -> 71368.931 | AD42: =AD$60*$E42 -> 108749.96 | AE42: =AE$60*$E42 -> 194196.35 | AG42: excess | AH42: 0 | AI42: =AI$61*$D42 -> 2401.6466 | AJ42: =AJ$61*$D42 -> 5603.842 | AK42: =AK$60*$E42 -> 8544.6394 | AL42: =AL$60*$E42 -> 11651.781
A43: =A44+1 -> 2011 | C43: ='CPI-U & C-CPI-U Calcs'!$L25 -> 1.2154093 | D43: ='CPI-U & C-CPI-U Calcs'!$P25 -> 1.563169 | E43: ='CPI-U & C-CPI-U Calcs'!$O25 -> 1.5167679 | F43: =F$51*$C43 -> 17015.73 | G43: =G$61*$D43 -> 69092.069 | H43: =H$61*$D43 -> 139356.51 | I43: =I$60*$E43 -> 212347.51 | J43: =J$60*$E43 -> 379191.99 | L43: excess | M43: =M$51*$C43 -> 8507.8648 | N43: =N$61*$D43 -> 34546.034 | O43: =O$61*$D43 -> 83629.54 | P43: =P$60*$E43 -> 174428.31 | Q43: =Q$60*$E43 -> 379191.99 | S43: excess | T43: =T$51*$C43 -> 12154.093 | U43: =U$61*$D43 -> 46269.802 | V43: =V$61*$D43 -> 119426.11 | W43: =W$60*$E43 -> 193387.91 | X43: =X$60*$E43 -> 379191.99 | Z43: excess | AA43: =AA$51*$C43 -> 8507.8648 | AB43: =AB$61*$D43 -> 34546.034 | AC43: =AC$61*$D43 -> 69678.257 | AD43: =AD$60*$E43 -> 106173.76 | AE43: =AE$60*$E43 -> 189595.99 | AG43: excess | AH43: 0 | AI43: =AI$61*$D43 -> 2344.7535 | AJ43: =AJ$61*$D43 -> 5471.0914 | AK43: =AK$60*$E43 -> 8342.2237 | AL43: =AL$60*$E43 -> 11375.76
A44: =A45+1 -> 2010 | C44: ='CPI-U & C-CPI-U Calcs'!$L26 -> 1.1977184 | D44: ='CPI-U & C-CPI-U Calcs'!$P26 -> 1.5404163 | E44: ='CPI-U & C-CPI-U Calcs'!$O26 -> 1.4946906 | F44: =F$51*$C44 -> 16768.057 | G44: =G$61*$D44 -> 68086.4 | H44: =H$61*$D44 -> 137328.11 | I44: =I$60*$E44 -> 209256.69 | J44: =J$60*$E44 -> 373672.66 | L44: excess | M44: =M$51*$C44 -> 8384.0287 | N44: =N$61*$D44 -> 34043.2 | O44: =O$61*$D44 -> 82412.272 | P44: =P$60*$E44 -> 171889.42 | Q44: =Q$60*$E44 -> 373672.66 | S44: excess | T44: =T$51*$C44 -> 11977.184 | U44: =U$61*$D44 -> 45596.322 | V44: =V$61*$D44 -> 117687.8 | W44: =W$60*$E44 -> 190573.06 | X44: =X$60*$E44 -> 373672.66 | Z44: excess | AA44: =AA$51*$C44 -> 8384.0287 | AB44: =AB$61*$D44 -> 34043.2 | AC44: =AC$61*$D44 -> 68664.056 | AD44: =AD$60*$E44 -> 104628.35 | AE44: =AE$60*$E44 -> 186836.33 | AG44: excess | AH44: 0 | AI44: =AI$61*$D44 -> 2310.6244 | AJ44: =AJ$61*$D44 -> 5391.457 | AK44: =AK$60*$E44 -> 8220.7986 | AL44: =AL$60*$E44 -> 11210.18
A45: =A46+1 -> 2009 | C45: ='CPI-U & C-CPI-U Calcs'!$L27 -> 1.1954946 | D45: ='CPI-U & C-CPI-U Calcs'!$P27 -> 1.5375562 | E45: ='CPI-U & C-CPI-U Calcs'!$O27 -> 1.4919155 | F45: =F$51*$C45 -> 16736.925 | G45: =G$61*$D45 -> 67959.986 | H45: =H$61*$D45 -> 137073.14 | I45: =I$60*$E45 -> 208868.17 | J45: =J$60*$E45 -> 372978.87 | L45: excess | M45: =M$51*$C45 -> 8368.4623 | N45: =N$61*$D45 -> 33979.993 | O45: =O$61*$D45 -> 82259.259 | P45: =P$60*$E45 -> 171570.28 | Q45: =Q$60*$E45 -> 372978.87 | S45: excess | T45: =T$51*$C45 -> 11954.946 | U45: =U$61*$D45 -> 45511.665 | V45: =V$61*$D45 -> 117469.3 | W45: =W$60*$E45 -> 190219.22 | X45: =X$60*$E45 -> 372978.87 | Z45: excess | AA45: =AA$51*$C45 -> 8368.4623 | AB45: =AB$61*$D45 -> 33979.993 | AC45: =AC$61*$D45 -> 68536.569 | AD45: =AD$60*$E45 -> 104434.08 | AE45: =AE$60*$E45 -> 186489.44 | AG45: excess | AH45: 0 | AI45: =AI$61*$D45 -> 2306.3344 | AJ45: =AJ$61*$D45 -> 5381.4468 | AK45: =AK$60*$E45 -> 8205.5352 | AL45: =AL$60*$E45 -> 11189.366
...

Sheet Tax Bracket (FUTURE)
D1: Inflation | G1: 0.0264
H2: Single | O2: Married Filing Jointly
F3: starting year | G3: 2003 | H3: 1993 | I3: 1993 | J3: 1994 | K3: 1994 | L3: 2013 | N3: 2003 | O3: 1993 | P3: 1993 | Q3: 1994 | R3: 1994 | S3: 2013
